<?xml version="1.0" encoding="utf-8"?>
<!-- This URDF was automatically created by SolidWorks to URDF Exporter! Originally created by Stephen Brawner (brawner@gmail.com) 
     Commit Version: 1.6.0-4-g7f85cfe  Build Version: 1.6.7995.38578
     For more information, please see http://wiki.ros.org/sw_urdf_exporter -->

<robot name="my_robot" xmlns:xacro="http://ros.org/wiki/xacro">

  <xacro:property name="mesh_path" value="package://arm_description/meshes/6DOF-2"/>

  <link
    name="base_link">
    <inertial>
      <origin
        xyz="0.00111653247184856 -2.47856588019062E-05 0.0350775423216737"
        rpy="0 0 0" />
      <mass
        value="0.214013778998518" />
      <inertia
        ixx="0.00014506059481398"
        ixy="-2.37847055524982E-12"
        ixz="1.27478119861964E-06"
        iyy="0.000147449505353298"
        iyz="-2.76699702605575E-14"
        izz="0.000223767943326789" />
    </inertial>
    <visual>
      <origin
        xyz="0 0 0"
        rpy="0 0 0" />
      <geometry>
        <mesh
          filename="${mesh_path}/base_link.STL" />
      </geometry>
      <material
        name="">
        <color
          rgba="0.792156862745098 0.819607843137255 0.933333333333333 1" />
      </material>
    </visual>
    <collision>
      <origin
        xyz="0 0 0"
        rpy="0 0 0" />
      <geometry>
        <mesh
          filename="${mesh_path}/base_link.STL" />
      </geometry>
    </collision>
  </link>
  <link
    name="link1">
    <inertial>
      <origin
        xyz="-3.30239519851079E-06 0.0170677308511169 0.0207459974530248"
        rpy="0 0 0" />
      <mass
        value="0.135893196407496" />
      <inertia
        ixx="8.16953377344433E-05"
        ixy="1.7747456586346E-08"
        ixz="5.1658703519188E-10"
        iyy="6.24198094411801E-05"
        iyz="1.88829979905978E-08"
        izz="0.000103378025391645" />
    </inertial>
    <visual>
      <origin
        xyz="0 0 0"
        rpy="0 0 0" />
      <geometry>
        <mesh
          filename="${mesh_path}/link1.STL" />
      </geometry>
      <material
        name="">
        <color
          rgba="0.792156862745098 0.819607843137255 0.933333333333333 1" />
      </material>
    </visual>
    <collision>
      <origin
        xyz="0 0 0"
        rpy="0 0 0" />
      <geometry>
        <mesh
          filename="${mesh_path}/link1.STL" />
      </geometry>
    </collision>
  </link>
  <joint
    name="joint1"
    type="revolute">
    <origin
      xyz="0 0 0.085"
      rpy="0 0 0" />
    <parent
      link="base_link" />
    <child
      link="link1" />
    <axis
      xyz="0 0 1" />
    <limit
      lower="-1.57"
      upper="1.57"
      effort="0"
      velocity="0" />
  </joint>
  <link
    name="link2">
    <inertial>
      <origin
        xyz="0.000436840828042232 -0.0679768380175993 0.000254476875340271"
        rpy="0 0 0" />
      <mass
        value="0.175235344220527" />
      <inertia
        ixx="0.000255022513735798"
        ixy="2.24897804370044E-09"
        ixz="5.40384385686437E-07"
        iyy="6.67645461061701E-05"
        iyz="1.12525106949762E-05"
        izz="0.000248867987979662" />
    </inertial>
    <visual>
      <origin
        xyz="0 0 0"
        rpy="0 0 0" />
      <geometry>
        <mesh
          filename="${mesh_path}/link2.STL" />
      </geometry>
      <material
        name="">
        <color
          rgba="0.792156862745098 0.819607843137255 0.933333333333333 1" />
      </material>
    </visual>
    <collision>
      <origin
        xyz="0 0 0"
        rpy="0 0 0" />
      <geometry>
        <mesh
          filename="${mesh_path}/link2.STL" />
      </geometry>
    </collision>
  </link>
  <joint
    name="joint2"
    type="revolute">
    <origin
      xyz="0 0 0.051"
      rpy="-1.5708 0 0" />
    <parent
      link="link1" />
    <child
      link="link2" />
    <axis
      xyz="0 0 -1" />
    <limit
      lower="-1.57"
      upper="1.57"
      effort="0"
      velocity="0" />
  </joint>
  <link
    name="link3">
    <inertial>
      <origin
        xyz="0.00731128167817027 0.0459386602638774 0.000173423468074263"
        rpy="0 0 0" />
      <mass
        value="0.0654362943169794" />
      <inertia
        ixx="2.39066743922144E-05"
        ixy="-5.92413205623402E-07"
        ixz="5.10085845703976E-09"
        iyy="2.89078640066287E-05"
        iyz="-1.06997422557498E-07"
        izz="2.20710311377657E-05" />
    </inertial>
    <visual>
      <origin
        xyz="0 0 0"
        rpy="0 0 0" />
      <geometry>
        <mesh
          filename="${mesh_path}/link3.STL" />
      </geometry>
      <material
        name="">
        <color
          rgba="0.792156862745098 0.819607843137255 0.933333333333333 1" />
      </material>
    </visual>
    <collision>
      <origin
        xyz="0 0 0"
        rpy="0 0 0" />
      <geometry>
        <mesh
          filename="${mesh_path}/link3.STL" />
      </geometry>
    </collision>
  </link>
  <joint
    name="joint3"
    type="revolute">
    <origin
      xyz="0 -0.1124 0"
      rpy="3.1416 0 1.5708" />
    <parent
      link="link2" />
    <child
      link="link3" />
    <axis
      xyz="0 0 1" />
    <limit
      lower="0"
      upper="3.14"
      effort="0"
      velocity="0" />
  </joint>
  <link
    name="link4">
    <inertial>
      <origin
        xyz="7.70593905120853E-05 0.00182905514254787 0.0376494628048921"
        rpy="0 0 0" />
      <mass
        value="0.0386078994649683" />
      <inertia
        ixx="1.92342011434751E-05"
        ixy="-6.41037581818175E-09"
        ixz="-7.81187102308395E-08"
        iyy="1.67673081393978E-05"
        iyz="2.05117616706914E-06"
        izz="6.64743882543711E-06" />
    </inertial>
    <visual>
      <origin
        xyz="0 0 0"
        rpy="0 0 0" />
      <geometry>
        <mesh
          filename="${mesh_path}/link4.STL" />
      </geometry>
      <material
        name="">
        <color
          rgba="0.792156862745098 0.819607843137255 0.933333333333333 1" />
      </material>
    </visual>
    <collision>
      <origin
        xyz="0 0 0"
        rpy="0 0 0" />
      <geometry>
        <mesh
          filename="${mesh_path}/link4.STL" />
      </geometry>
    </collision>
  </link>
  <joint
    name="joint4"
    type="revolute">
    <origin
      xyz="0 0.075 0"
      rpy="1.5708 0 3.1416" />
    <parent
      link="link3" />
    <child
      link="link4" />
    <axis
      xyz="0 0 1" />
    <limit
      lower="-1.57"
      upper="1.57"
      effort="0"
      velocity="0" />
  </joint>
  <link
    name="link5">
    <inertial>
      <origin
        xyz="-0.0184256820448302 0.0453821355916177 0.000351559170909365"
        rpy="0 0 0" />
      <mass
        value="0.0534727652815745" />
      <inertia
        ixx="1.69983989756949E-05"
        ixy="1.74850231865527E-06"
        ixz="-2.14843265029993E-07"
        iyy="2.06994207429218E-05"
        iyz="1.71721108289366E-07"
        izz="2.17164666109225E-05" />
    </inertial>
    <visual>
      <origin
        xyz="0 0 0"
        rpy="0 0 0" />
      <geometry>
        <mesh
          filename="${mesh_path}/link5.STL" />
      </geometry>
      <material
        name="">
        <color
          rgba="0.792156862745098 0.819607843137255 0.933333333333333 1" />
      </material>
    </visual>
    <collision>
      <origin
        xyz="0 0 0"
        rpy="0 0 0" />
      <geometry>
        <mesh
          filename="${mesh_path}/link5.STL" />
      </geometry>
    </collision>
  </link>
  <joint
    name="joint5"
    type="revolute">
    <origin
      xyz="0 0 0.052"
      rpy="1.5708 0 0" />
    <parent
      link="link4" />
    <child
      link="link5" />
    <axis
      xyz="0 0 -1" />
    <limit
      lower="-1.57"
      upper="1.57"
      effort="0"
      velocity="0" />
  </joint>
  <link
    name="link6">
    <inertial>
      <origin
        xyz="0.0037332392922132 -0.00385606800350177 0.0173805970971101"
        rpy="0 0 0" />
      <mass
        value="0.00231539418970362" />
      <inertia
        ixx="3.57098871983819E-07"
        ixy="-4.07234095114581E-08"
        ixz="1.66638479445446E-08"
        iyy="3.59774075029641E-07"
        iyz="-1.72177633493782E-08"
        izz="2.79037471422483E-07" />
    </inertial>
    <visual>
      <origin
        xyz="0 0 0"
        rpy="0 0 0" />
      <geometry>
        <mesh
          filename="${mesh_path}/link6.STL" />
      </geometry>
      <material
        name="">
        <color
          rgba="0.792156862745098 0.819607843137255 0.933333333333333 1" />
      </material>
    </visual>
    <collision>
      <origin
        xyz="0 0 0"
        rpy="0 0 0" />
      <geometry>
        <mesh
          filename="${mesh_path}/link6.STL" />
      </geometry>
    </collision>
  </link>
  <joint
    name="joint6"
    type="revolute">
    <origin
      xyz="-0.01 0.0685 0"
      rpy="-1.5708 0 0" />
    <parent
      link="link5" />
    <child
      link="link6" />
    <axis
      xyz="0 0 1" />
    <limit
      lower="-1.57"
      upper="1.57"
      effort="0"
      velocity="0" />
  </joint>
</robot>